#VRML_SIM R2023b utf8

EXTERNPROTO "https://raw.githubusercontent.com/cyberbotics/webots/R2023b/projects/appearances/protos/Asphalt.proto"
EXTERNPROTO "https://raw.githubusercontent.com/cyberbotics/webots/R2023b/projects/objects/backgrounds/protos/TexturedBackground.proto"
EXTERNPROTO "https://raw.githubusercontent.com/cyberbotics/webots/R2023b/projects/objects/backgrounds/protos/TexturedBackgroundLight.proto"
EXTERNPROTO "https://raw.githubusercontent.com/cyberbotics/webots/R2023b/projects/objects/floors/protos/UnevenTerrain.proto"

WorldInfo {
}
Viewpoint {
  orientation -0.17857164600875444 0.27195456335392526 0.9455965750322385 1.213932376090762
  position -0.8774352144947473 -14.110428108756143 9.56004008495989
}
TexturedBackground {
}
TexturedBackgroundLight {
}
Robot {
  translation 5.879003752598825 -0.02909208487228492 3.659919331903652
  rotation 0.8183448101997627 -0.573623290327207 0.03561028521794103 0.07930760317984982
  children [
    InertialUnit {
    }
    DEF torso Shape {
      appearance PBRAppearance {
        baseColor 0.6 0.6 1
        metalness 0
      }
      geometry Box {
        size 1 1 0.2
      }
    }
    DEF wheel HingeJoint {
      jointParameters HingeJointParameters {
        position 32.79968785843845
        axis 0 1 0
        anchor -0.3 -0.577883 -0.0631591
      }
      device [
        RotationalMotor {
          name "motor1"
        }
      ]
      endPoint Solid {
        translation -0.3 -0.577883 -0.0631591
        rotation 0.6432816327941628 -0.5496742083162132 -0.5329606041928617 4.3131441990574295
        children [
          DEF wheel_body Shape {
            appearance Asphalt {
            }
            geometry Cylinder {
              height 0.2
              radius 0.18
            }
          }
        ]
        boundingObject USE wheel_body
        physics DEF phy1 Physics {
          mass 1
        }
        linearVelocity -3.5938511592110675e-06 -4.7411515619297774e-06 -5.355487758720318e-07
        angularVelocity -1.850967570909003e-09 -1.3215456208966747e-06 3.780763803181194e-07
      }
    }
    DEF wheel HingeJoint {
      jointParameters HingeJointParameters {
        position 32.79646699215142
        axis 0 1 0
        anchor 0.3 -0.577883 -0.0631591
      }
      device [
        RotationalMotor {
          name "motor2"
        }
      ]
      endPoint Solid {
        translation 0.3 -0.577883 -0.0631591
        rotation 0.6445176155310602 -0.5489274267695976 -0.5322365295714533 4.314913424162347
        children [
          DEF wheel_body Shape {
            appearance Asphalt {
            }
            geometry Cylinder {
              height 0.2
              radius 0.18
            }
          }
        ]
        name "solid(1)"
        boundingObject USE wheel_body
        physics DEF phy1 Physics {
          mass 1
        }
        linearVelocity -3.5974915615826194e-06 -4.4675965059051036e-06 -4.6376128972269474e-07
        angularVelocity -1.9650072083038027e-09 -1.2943788150436285e-06 3.7983977627000533e-07
      }
    }
    DEF wheel HingeJoint {
      jointParameters HingeJointParameters {
        position 32.7990478293245
        axis 0 1 0
        anchor 0.3 0.577883 -0.0631591
      }
      device [
        RotationalMotor {
          name "motor3"
        }
      ]
      endPoint Solid {
        translation 0.3 0.577883 -0.0631591
        rotation 0.643527257168435 -0.5495259967967191 -0.532816899249492 4.313495959128961
        children [
          DEF wheel_body Shape {
            appearance Asphalt {
            }
            geometry Cylinder {
              height 0.2
              radius 0.18
            }
          }
        ]
        name "solid(2)"
        boundingObject USE wheel_body
        physics DEF phy1 Physics {
          mass 1
        }
        linearVelocity -4.132465870703368e-06 -4.469336733252675e-06 -4.724485681890644e-07
        angularVelocity -5.011772123253016e-09 -5.921792053994968e-07 4.254161637555559e-07
      }
    }
    DEF wheel HingeJoint {
      jointParameters HingeJointParameters {
        position 32.80001328451732
        axis 0 1 0
        anchor -0.3 0.577883 -0.0631591
      }
      device [
        RotationalMotor {
          name "motor4"
        }
      ]
      endPoint Solid {
        translation -0.3 0.577883 -0.0631591
        rotation 0.643156740415998 -0.5497495322611867 -0.5330336378091678 4.312965308478338
        children [
          DEF wheel_body Shape {
            appearance Asphalt {
            }
            geometry Cylinder {
              height 0.2
              radius 0.18
            }
          }
        ]
        name "solid(3)"
        boundingObject USE wheel_body
        physics DEF phy1 Physics {
          mass 1
        }
        linearVelocity -4.128819127343405e-06 -4.742883609146995e-06 -5.443561148013002e-07
        angularVelocity -1.7337193131664276e-09 -1.3547440525299481e-06 3.7592122123545867e-07
      }
    }
  ]
  boundingObject USE torso
  physics USE phy1
  controller "my_controller"
  linearVelocity -3.868835569885931e-06 -4.606105016297768e-06 -5.043432215643406e-07
  angularVelocity -7.043907765820828e-09 -1.19884108425009e-07 4.5607012923959145e-07
}
UnevenTerrain {
}
